Workbook

Sheet Project Plan
A1: Odysee — Personal AI Travel Companion · Project Plan
A2: David Castiel | M.Design · HIT | הגשת ספר 4.8.2026 · תערוכה 6–19.8.2026 | עודכן 7.6.2026 — תאריכים = strawman, לתיקון
A4: # | B4: פאזה | C4: משימה | D4: תאריך התחלה | E4: תאריך סיום | F4: משך (ימים) | G4: סטטוס | H4: הערות
A5: ספר — Book (freeze ~26.7 · הגשה 4.8)
A6: 1 | B6: ספר | C6: ✅ פרקים 1–6 (טיוטה) | D6: 46127 | E6: 46159 | F6: =E6-D6+1 -> 33 | G6: DOCS | H6: מבוא·רקע·קונספט·ארכיטקטורה·UX·מערכת עיצוב — טיוטה גמורה
A7: 2 | B7: ספר | C7: ✅ פרק 8 "הדור הבא" + ביבליוגרפיה (41) | D7: 46162 | E7: 46165 | F7: =E7-D7+1 -> 4 | G7: DOCS | H7: נכתב ושולב; הדיון הפך לפרק 9
A8: 3 | B8: ספר | C8: ✅ איורים פרקים 2/4/5 (וקטורי) | D8: 46170 | E8: 46173 | F8: =E8-D8+1 -> 4 | G8: DESIGN | H8: משפך אמון · מפת 11 סוכנים · journey map · 5 מסכים
A9: 4 | B9: ספר | C9: ✅ שכתוב פרק 6 ל-Brand V5 | D9: 46176 | E9: 46185 | F9: =E9-D9+1 -> 10 | G9: DESIGN | H9: מתעד מותג בן-שני-דורות; יחד עם design-system.html
A10: 5 | B10: ספר | C10: פיגורת לוגו + משפט-יישוב פרק 8 (V5) | D10: 46181 | E10: 46187 | F10: =E10-D10+1 -> 7 | G10: DESIGN | H10: יישוב הפנים מול companion≠oracle
A11: 6 | B11: ספר | C11: אימות ביבליוגרפיה (כולל מקור ה-89%) | D11: 46183 | E11: 46195 | F11: =E11-D11+1 -> 13 | G11: KEY | H11: 89%→Phocuswright? · Chile 21.383 · פטנט Apple · Nature MI — סיכון בוחן
A12: 7 | B12: ספר | C12: עריכת ניסוחים — כל הפרקים (Word flow) | D12: 46188 | E12: 46218 | F12: =E12-D12+1 -> 31 | G12: CONTENT | H12: David עורך ב-Word → החלה עדינה על ה-tex
A13: 8 | B13: ספר | C13: פרק 7 (תערוכה) | D13: 46201 | E13: 46215 | F13: =E13-D13+1 -> 15 | G13: KEY | H13: חסום ל-spec + מיפוי סוף יוני
A14: 9 | B14: ספר | C14: פרק 9 (דיון) | D14: 46211 | E14: 46221 | F14: =E14-D14+1 -> 11 | G14: DOCS | H14: נכתב לקראת הסוף
A15: 10 | B15: ספר | C15: Abstract אנגלית + עברית | D15: 46218 | E15: 46223 | F15: =E15-D15+1 -> 6 | G15: DOCS | H15: לפי תקנון HIT
A16: 11 | B16: ספר | C16: הקפאת תוכן + הגהה + בנייה סופית | D16: 46223 | E16: 46229 | F16: =E16-D16+1 -> 7 | G16: KEY | H16: freeze מוקדם — לא ב-4.8
A17: 12 | B17: ספר | C17: הדפסה + כריכה | D17: 46231 | E17: 46236 | F17: =E17-D17+1 -> 6 | G17: PRINT | H17: דורש קבצים סופיים שבוע מראש
A18: אתר — Site (rebrand-v5 → main)
A19: 13 | B19: אתר | C19: ✅ מיגרציה Brand v1.0 + IA + next-generation | D19: 46160 | E19: 46165 | F19: =E19-D19+1 -> 6 | G19: DESIGN | H19: 5 עמודים + book/exhibition Coming Soon
A20: 14 | B20: אתר | C20: ✅ rebrand V5: 8 לוגואים→פנים + צבעים | D20: 46171 | E20: 46171 | F20: =E20-D20+1 -> 1 | G20: DESIGN | H20: ענף rebrand-v5
A21: 15 | B21: אתר | C21: ✅ שכתוב design-system.html + hero-mark→פנים | D21: 46176 | E21: 46185 | F21: =E21-D21+1 -> 10 | G21: DESIGN | H21: יחד עם פרק 6 בספר
A22: 16 | B22: אתר | C22: ✅ תיקון agents.html ל-4 סוכנים חיים | D22: 46177 | E22: 46179 | F22: =E22-D22+1 -> 3 | G22: FIX | H22: סתירה ספר↔אתר (AGT-04 עדיין קונספטואלי באתר)
A23: 17 | B23: אתר | C23: Plus Jakarta Sans (גוף) + favicon.svg | D23: 46183 | E23: 46187 | F23: =E23-D23+1 -> 5 | G23: DEV | H23: עברית נשארת Heebo
A24: 18 | B24: אתר | C24: איחוד .brand-mark*+טוקנים לקובץ משותף | D24: 46185 | E24: 46191 | F24: =E24-D24+1 -> 7 | G24: DEV | H24: חוב טכני — לפני שינויי מותג נוספים
A25: 19 | B25: אתר | C25: exhibition.html | D25: 46201 | E25: 46213 | F25: =E25-D25+1 -> 13 | G25: DESIGN | H25: חסום ל-spec של HIT
A26: 20 | B26: אתר | C26: QA light/dark/mobile/RTL + OG image | D26: 46215 | E26: 46221 | F26: =E26-D26+1 -> 7 | G26: QA
A27: 21 | B27: אתר | C27: מיזוג rebrand-v5→main + פריסת GH Pages | D27: 46221 | E27: 46223 | F27: =E27-D27+1 -> 3 | G27: DEV | H27: ודא .claude/worktrees ב-gitignore
A28: 22 | B28: אתר | C28: מיגרציית project-plan.html (לא דחוף) | D28: 46223 | E28: 46227 | F28: =E28-D28+1 -> 5 | G28: DESIGN | H28: legacy RTL
A29: אפליקציה + דמו — App & Demo ◀ נתיב קריטי
A30: 23 | B30: אפליקציה | C30: ✅ pipeline עובד (STT→agents→TTS) | D30: 46143 | E30: 46170 | F30: =E30-D30+1 -> 28 | G30: DEV | H30: רץ יחסית טוב
A31: 24 | B31: אפליקציה | C31: ✅ 4 סוכנים עובדים בעיקרון (01/02/04/06) | D31: 46143 | E31: 46170 | F31: =E31-D31+1 -> 28 | G31: IMPL
A32: 25 | B32: אפליקציה | C32: ✅ tico-orb כפנים (idle/listen/think/speak) | D32: 46171 | E32: 46171 | F32: =E32-D32+1 -> 1 | G32: DEV | H32: state machine + Web Audio
A33: 26 | B33: אפליקציה | C33: עיצוב + ליטוש UI של הדמו | D33: 46176 | E33: 46207 | F33: =E33-D33+1 -> 32 | G33: DESIGN | H33: "חסר לא מעט" — לב הנתיב הקריטי
A34: 27 | B34: אפליקציה | C34: חיבור tico-orb ל-TTS envelope + VAD | D34: 46181 | E34: 46191 | F34: =E34-D34+1 -> 11 | G34: DEV | H34: פה לפי אמפליטודה; מעברי-מצב
A35: 28 | B35: אפליקציה | C35: AGT-06 אימות מקצה-לקצה | D35: 46183 | E35: 46189 | F35: =E35-D35+1 -> 7 | G35: DEV | H35: frontend לא אומת בזרימה מלאה
A36: 29 | B36: אפליקציה | C36: מודל אינטראקציה PTT (hold מול tap+silence) | D36: 46188 | E36: 46198 | F36: =E36-D36+1 -> 11 | G36: KEY | H36: להחליט בבדיקה; Stream Deck Neo
A37: 30 | B37: אפליקציה | C37: demo-mode לנפילת רשת (fallback ל-6 APIs) | D37: 46193 | E37: 46208 | F37: =E37-D37+1 -> 16 | G37: KEY | H37: חובה — קו סלולרי בודד
A38: 31 | B38: אפליקציה | C38: attract-loop + תוכן שיחה לקהל | D38: 46204 | E38: 46215 | F38: =E38-D38+1 -> 12 | G38: CONTENT | H38: edge cases · תשובות ל-100–200 מבקרים
A39: 32 | B39: אפליקציה | C39: שליחת מסלול שנבנה למבקר (QR → PDF) | D39: 46188 | E39: 46196 | F39: =E39-D39+1 -> 9 | G39: DEV | H39: שכבת must-have הושלמה ואומתה e2e (generate_takeaway→R2→QR→PDF). email נהרג (PII). נותר: trigger דרך Stream Deck + commit
A40: 33 | B40: אפליקציה | C40: אסטרטגיית תקציב TTS (שדרוג מ-NO_TTS) | D40: 46208 | E40: 46213 | F40: =E40-D40+1 -> 6 | G40: KEY
A41: 34 | B41: אפליקציה | C41: (אופ') מנגנון interrupt "תעצור"/barge-in | D41: 46211 | E41: 46218 | F41: =E41-D41+1 -> 8 | G41: DEV | H41: נדחה; רלוונטי לקהל חי
...

Sheet Track Summary
A1: Track Summary
A2: Track | B2: Name | C2: Start | D2: End | E2: Duration | F2: Focus
A3: ספר | B3: ספר | C3: =MIN('Project Plan'!D6:D17) -> 46127 | D3: =MAX('Project Plan'!E6:E17) -> 46236 | E3: =D3-C3+1 -> 110 | F3: טיוטה + rebrand פ'6 ✅ · נותר: פ'7, פ'9, אנגלית, ביבליו', הגהה, הדפסה
A4: אתר | B4: אתר | C4: =MIN('Project Plan'!D19:D28) -> 46160 | D4: =MAX('Project Plan'!E19:E28) -> 46227 | E4: =D4-C4+1 -> 68 | F4: מיגרציה + design-system + agents ✅ · נותר: פונט/favicon, איחוד טוקנים, exhibition, QA, מיזוג
A5: אפליקציה | B5: אפליקציה + דמו | C5: =MIN('Project Plan'!D30:D45) -> 46143 | D5: =MAX('Project Plan'!E30:E45) -> 46231 | E5: =D5-C5+1 -> 89 | F5: pipeline + 4 סוכנים ✅ · נותר: ליטוש UI, demo-mode, PTT, export/QR, pilot — קריטי
A6: תערוכה | B6: תערוכה / לוגיסטיקה | C6: =MIN('Project Plan'!D47:D60) -> 46171 | D6: =MAX('Project Plan'!E47:E60) -> 46254 | E6: =D6-C6+1 -> 84 | F6: החלטות חלל ✅ · נותר: spec, מיפוי, חשמל, Mac mini, פוסטר, הקמה, פירוק
A7: אבן דרך | B7: אבני דרך | C7: =MIN('Project Plan'!D62:D67) -> 46175 | D7: =MAX('Project Plan'!E62:E67) -> 46240 | E7: =D7-C7+1 -> 66 | F7: פגישת מנחה · הצגת ביניים · freeze · dry-run · הגשה · פתיחה
